Workbook

Sheet summary
A1: data_type | B1: gantry | C1: gantry_angle | D1: energy | E1: fwhm
A2: tps | B2: 1 | C2: 90 | D2: 70 | E2: =VLOOKUP(D2,TPS!$A$6:$H$41,8,FALSE) -> 13.562493 | I2: Sheet | J2: Checked | L2: I have checked each sheet's data with comparison to the source data (location at the top of each individual sheet). This includes TPS data, plus gantry specific spot data for each of the four gantries. To the best of my ability, I am happy that they are an accurate representation of the data, save for some differences in rounding. HC, 01/06/2026.
A3: tps | B3: 1 | C3: 90 | D3: 100 | E3: =VLOOKUP(D3,TPS!$A$6:$H$41,8,FALSE) -> 11.177229 | I3: TPS | J3: x
A4: tps | B4: 1 | C4: 90 | D4: 150 | E4: =VLOOKUP(D4,TPS!$A$6:$H$41,8,FALSE) -> 9.0818446 | I4: G1_GA0 | J4: x
A5: tps | B5: 1 | C5: 90 | D5: 200 | E5: =VLOOKUP(D5,TPS!$A$6:$H$41,8,FALSE) -> 8.1718857 | I5: G1_GA90 | J5: x
A6: tps | B6: 1 | C6: 90 | D6: 240 | E6: =VLOOKUP(D6,TPS!$A$6:$H$41,8,FALSE) -> 7.409863 | I6: G1_GA180 | J6: x
A7: baseline | B7: 1 | C7: 0 | D7: 70 | E7: =VLOOKUP(D7,G1_GA0!$A$6:$H$41,8,FALSE) -> 13.696196 | I7: G1_GA270 | J7: x
A8: baseline | B8: 1 | C8: 0 | D8: 100 | E8: =VLOOKUP(D8,G1_GA0!$A$6:$H$41,8,FALSE) -> 11.267367 | I8: G2_GA0 | J8: x
A9: baseline | B9: 1 | C9: 0 | D9: 150 | E9: =VLOOKUP(D9,G1_GA0!$A$6:$H$41,8,FALSE) -> 9.244249 | I9: G2_GA0_annual | J9: x
A10: baseline | B10: 1 | C10: 0 | D10: 200 | E10: =VLOOKUP(D10,G1_GA0!$A$6:$H$41,8,FALSE) -> 8.2458698 | I10: G2_GA90 | J10: x
A11: baseline | B11: 1 | C11: 0 | D11: 240 | E11: =VLOOKUP(D11,G1_GA0!$A$6:$H$41,8,FALSE) -> 7.7620543 | I11: G2_GA180 | J11: x
A12: baseline | B12: 1 | C12: 90 | D12: 70 | E12: =VLOOKUP(D12,G1_GA90!$A$6:$H$41,8,FALSE) -> 13.903965 | I12: G2_GA270 | J12: x
A13: baseline | B13: 1 | C13: 90 | D13: 100 | E13: =VLOOKUP(D13,G1_GA90!$A$6:$H$41,8,FALSE) -> 11.157795 | I13: G3_GA0 | J13: x
A14: baseline | B14: 1 | C14: 90 | D14: 150 | E14: =VLOOKUP(D14,G1_GA90!$A$6:$H$41,8,FALSE) -> 9.3371513 | I14: G3_GA90 | J14: x
A15: baseline | B15: 1 | C15: 90 | D15: 200 | E15: =VLOOKUP(D15,G1_GA90!$A$6:$H$41,8,FALSE) -> 8.3988573 | I15: G3_GA180 | J15: x
A16: baseline | B16: 1 | C16: 90 | D16: 240 | E16: =VLOOKUP(D16,G1_GA90!$A$6:$H$41,8,FALSE) -> 7.7800353 | I16: G3_GA270 | J16: x
A17: baseline | B17: 1 | C17: 180 | D17: 70 | E17: =VLOOKUP(D17,G1_GA180!$A$6:$H$41,8,FALSE) -> 13.915793 | I17: G4_GA0 | J17: x
A18: baseline | B18: 1 | C18: 180 | D18: 100 | E18: =VLOOKUP(D18,G1_GA180!$A$6:$H$41,8,FALSE) -> 11.366865 | I18: G4_GA90 | J18: x
A19: baseline | B19: 1 | C19: 180 | D19: 150 | E19: =VLOOKUP(D19,G1_GA180!$A$6:$H$41,8,FALSE) -> 9.3090441 | I19: G4_GA180 | J19: x
A20: baseline | B20: 1 | C20: 180 | D20: 200 | E20: =VLOOKUP(D20,G1_GA180!$A$6:$H$41,8,FALSE) -> 8.5053222 | I20: G4_GA270 | J20: x
A21: baseline | B21: 1 | C21: 180 | D21: 240 | E21: =VLOOKUP(D21,G1_GA180!$A$6:$H$41,8,FALSE) -> 7.9821384
A22: baseline | B22: 1 | C22: 270 | D22: 70 | E22: =VLOOKUP(D22,G1_GA270!$A$6:$I$41,8,FALSE) -> 13.965417
A23: baseline | B23: 1 | C23: 270 | D23: 100 | E23: =VLOOKUP(D23,G1_GA270!$A$6:$I$41,8,FALSE) -> 11.292832
A24: baseline | B24: 1 | C24: 270 | D24: 150 | E24: =VLOOKUP(D24,G1_GA270!$A$6:$I$41,8,FALSE) -> 9.3600431
A25: baseline | B25: 1 | C25: 270 | D25: 200 | E25: =VLOOKUP(D25,G1_GA270!$A$6:$I$41,8,FALSE) -> 8.5463294
A26: baseline | B26: 1 | C26: 270 | D26: 240 | E26: =VLOOKUP(D26,G1_GA270!$A$6:$I$41,8,FALSE) -> 7.9485055
A27: baseline | B27: 2 | C27: 0 | D27: 70 | E27: =VLOOKUP(D27,G2_GA0_annual!$A$6:$H$41,8,FALSE) -> 14.22953
A28: baseline | B28: 2 | C28: 0 | D28: 100 | E28: =VLOOKUP(D28,G2_GA0_annual!$A$6:$H$41,8,FALSE) -> 11.467361
A29: baseline | B29: 2 | C29: 0 | D29: 150 | E29: =VLOOKUP(D29,G2_GA0_annual!$A$6:$H$41,8,FALSE) -> 9.4681657
A30: baseline | B30: 2 | C30: 0 | D30: 200 | E30: =VLOOKUP(D30,G2_GA0_annual!$A$6:$H$41,8,FALSE) -> 8.7419948
A31: baseline | B31: 2 | C31: 0 | D31: 240 | E31: =VLOOKUP(D31,G2_GA0_annual!$A$6:$H$41,8,FALSE) -> 8.0884334
A32: baseline | B32: 2 | C32: 90 | D32: 70 | E32: =VLOOKUP(D32,G2_GA90!$A$6:$H$41, 8,FALSE) -> 14.272
A33: baseline | B33: 2 | C33: 90 | D33: 100 | E33: =VLOOKUP(D33,G2_GA90!$A$6:$H$41, 8,FALSE) -> 11.481342
A34: baseline | B34: 2 | C34: 90 | D34: 150 | E34: =VLOOKUP(D34,G2_GA90!$A$6:$H$41, 8,FALSE) -> 9.5962188
A35: baseline | B35: 2 | C35: 90 | D35: 200 | E35: =VLOOKUP(D35,G2_GA90!$A$6:$H$41, 8,FALSE) -> 8.7732895
A36: baseline | B36: 2 | C36: 90 | D36: 240 | E36: =VLOOKUP(D36,G2_GA90!$A$6:$H$41, 8,FALSE) -> 7.2870545
A37: baseline | B37: 2 | C37: 180 | D37: 70 | E37: =VLOOKUP(D37,G2_GA180!$A$6:$H$41,8,FALSE) -> 14.411943
A38: baseline | B38: 2 | C38: 180 | D38: 100 | E38: =VLOOKUP(D38,G2_GA180!$A$6:$H$41,8,FALSE) -> 11.553562
A39: baseline | B39: 2 | C39: 180 | D39: 150 | E39: =VLOOKUP(D39,G2_GA180!$A$6:$H$41,8,FALSE) -> 9.4759021
A40: baseline | B40: 2 | C40: 180 | D40: 200 | E40: =VLOOKUP(D40,G2_GA180!$A$6:$H$41,8,FALSE) -> 8.6085606
...

Sheet TPS
A1: TPS spot size without RS
A2: C:\Users\KALONGMA\NHS\(Canc) Radiotherapy - PBT Physics Team - PBT Physics Team\Treatment_Planning\Gantry1\Profiles\Fits_G90_RS0_Dist0.xlsx
B4: Single Gaussian Fit
A5: Energy | B5: amplitude | C5: x_mean | D5: y_mean | E5: x_stddev | F5: y_stddev | G5: ave_stddev | H5: ave_fwhm | I5: theta | J5: amplitude
A6: 70 | B6: 1 | C6: 0.028288042 | D6: 0.32289538 | E6: 5.8385603 | F6: 5.7039869 | G6: =AVERAGE(E6:F6) -> 5.7712736 | H6: =2.35*G6 -> 13.562493 | I6: 0 | J6: 0.91219304
A7: 75 | B7: 1 | C7: 0.21297735 | D7: 0.30027618 | E7: 5.6284227 | F7: 5.4421216 | G7: =AVERAGE(E7:F7) -> 5.5352721 | H7: =2.35*G7 -> 13.00789 | I7: 0 | J7: 0.98421545
A8: 80 | B8: 1 | C8: 0.05023102 | D8: 0.55017642 | E8: 5.4604872 | F8: 5.2555148 | G8: =AVERAGE(E8:F8) -> 5.358001 | H8: =2.35*G8 -> 12.591302 | I8: 0 | J8: 0.99440534
A9: 85 | B9: 1 | C9: 0.094418609 | D9: 0.32010271 | E9: 5.1857203 | F9: 5.0012418 | G9: =AVERAGE(E9:F9) -> 5.0934811 | H9: =2.35*G9 -> 11.96968 | I9: 0 | J9: 0.98648633
A10: 90 | B10: 1 | C10: 0.10433474 | D10: 0.15914975 | E10: 5.0863498 | F10: 4.9091871 | G10: =AVERAGE(E10:F10) -> 4.9977684 | H10: =2.35*G10 -> 11.744756 | I10: 0 | J10: 0.99570622
A11: 95 | B11: 0.99440373 | C11: 0.27840102 | D11: 0.23070678 | E11: 4.933889 | F11: 4.7752006 | G11: =AVERAGE(E11:F11) -> 4.8545448 | H11: =2.35*G11 -> 11.40818 | I11: 0 | J11: 0.99544485
A12: 100 | B12: 1 | C12: 0.38409536 | D12: 0.40817422 | E12: 4.8301233 | F12: 4.6824124 | G12: =AVERAGE(E12:F12) -> 4.7562679 | H12: =2.35*G12 -> 11.177229 | I12: 0 | J12: 0.86257913
A13: 105 | B13: 1 | C13: 0.18107559 | D13: 0.40347581 | E13: 4.7020452 | F13: 4.5795199 | G13: =AVERAGE(E13:F13) -> 4.6407826 | H13: =2.35*G13 -> 10.905839 | I13: 0 | J13: 0.88678368
A14: 110 | B14: 1 | C14: 0.26715227 | D14: 0.2828898 | E14: 4.5742855 | F14: 4.4813277 | G14: =AVERAGE(E14:F14) -> 4.5278066 | H14: =2.35*G14 -> 10.640346 | I14: 0 | J14: 0.95667424
A15: 115 | B15: 1 | C15: 0.13412496 | D15: 0.11756602 | E15: 4.4596968 | F15: 4.3738525 | G15: =AVERAGE(E15:F15) -> 4.4167746 | H15: =2.35*G15 -> 10.37942 | I15: 0 | J15: 0.84675443
A16: 120 | B16: 1 | C16: 0.35186611 | D16: 0.27325612 | E16: 4.4029736 | F16: 4.349875 | G16: =AVERAGE(E16:F16) -> 4.3764243 | H16: =2.35*G16 -> 10.284597 | I16: 0 | J16: 0.90515593
A17: 125 | B17: 1 | C17: 0.18764133 | D17: 0.35082557 | E17: 4.2733651 | F17: 4.2569836 | G17: =AVERAGE(E17:F17) -> 4.2651744 | H17: =2.35*G17 -> 10.02316 | I17: 0 | J17: 0.88132434
... A41: 245 | B41: 1 | C41: -0.0078747841 | D41: 0.30068562 | E41: 3.0544853 | F41: 2.9046043 | G41: =AVERAGE(E41:F41) -> 2.9795448 | H41: =2.35*G41 -> 7.0019303 | I41: 0 | J41: 1

Sheet G1_GA0
A1: Gantry 1 GA0 data
A2: T:\Routine QA\Annual Checks\G1\2023\Profiles\Fits_G0_RS0_Dist0_2023.xlsx
B4: Single Gaussian Fit
A5: Energy | B5: amplitude | C5: x_mean | D5: y_mean | E5: x_stddev | F5: y_stddev | G5: ave_stddev | H5: ave_fwhm | I5: theta | J5: amplitude
A6: 70 | B6: 1 | C6: 0.099645025 | D6: 0.67425289 | E6: 5.7891181 | F6: 5.8672192 | G6: =AVERAGE(E6:F6) -> 5.8281686 | H6: =G6*2.35 -> 13.696196 | I6: 0 | J6: 0.7
A7: 75 | B7: 1 | C7: 0.06950155 | D7: 0.34100039 | E7: 5.5187222 | F7: 5.5981708 | G7: =AVERAGE(E7:F7) -> 5.5584465 | H7: =G7*2.35 -> 13.062349 | I7: 0 | J7: 0.95254507
A8: 80 | B8: 1 | C8: 0.12984233 | D8: 0.41342935 | E8: 5.3616515 | F8: 5.4257119 | G8: =AVERAGE(E8:F8) -> 5.3936817 | H8: =G8*2.35 -> 12.675152 | I8: 0 | J8: 0.99043767
A9: 85 | B9: 1 | C9: 0.31515405 | D9: 0.39251507 | E9: 5.1822949 | F9: 5.2279871 | G9: =AVERAGE(E9:F9) -> 5.205141 | H9: =G9*2.35 -> 12.232081 | I9: 0 | J9: 0.99196966
A10: 90 | B10: 1 | C10: 0.26922881 | D10: 0.3093282 | E10: 5.0835003 | F10: 5.0993705 | G10: =AVERAGE(E10:F10) -> 5.0914354 | H10: =G10*2.35 -> 11.964873 | I10: 0 | J10: 0.86663967
A11: 95 | B11: 1 | C11: 0.078897202 | D11: 0.12375432 | E11: 4.9157879 | F11: 4.9129172 | G11: =AVERAGE(E11:F11) -> 4.9143526 | H11: =G11*2.35 -> 11.548729 | I11: 0 | J11: 0.9956325
A12: 100 | B12: 1 | C12: 0.34722644 | D12: 0.30153374 | E12: 4.8026135 | F12: 4.7866353 | G12: =AVERAGE(E12:F12) -> 4.7946244 | H12: =G12*2.35 -> 11.267367 | I12: 0 | J12: 0.85165728
A13: 105 | B13: 1 | C13: 0.091089997 | D13: 0.61336451 | E13: 4.6466074 | F13: 4.6207459 | G13: =AVERAGE(E13:F13) -> 4.6336767 | H13: =G13*2.35 -> 10.88914 | I13: 0 | J13: 0.87270334
A14: 110 | B14: 1 | C14: 0.42226137 | D14: 0.39031627 | E14: 4.6009807 | F14: 4.5726597 | G14: =AVERAGE(E14:F14) -> 4.5868202 | H14: =G14*2.35 -> 10.779027 | I14: 0 | J14: 0.86478501
A15: 115 | B15: 1 | C15: 0.10549526 | D15: 0.2642095 | E15: 4.4624789 | F15: 4.4265907 | G15: =AVERAGE(E15:F15) -> 4.4445348 | H15: =G15*2.35 -> 10.444657 | I15: 0 | J15: 0.87170812
A16: 120 | B16: 1 | C16: 0.38229117 | D16: 0.35201372 | E16: 4.3475617 | F16: 4.2993338 | G16: =AVERAGE(E16:F16) -> 4.3234477 | H16: =G16*2.35 -> 10.160102 | I16: 0 | J16: 0.83376592
A17: 125 | B17: 1 | C17: 0.44307376 | D17: 0.17445461 | E17: 4.3243341 | F17: 4.2648487 | G17: =AVERAGE(E17:F17) -> 4.2945914 | H17: =G17*2.35 -> 10.09229 | I17: 0 | J17: 0.86216301
... A41: 245 | B41: 1 | C41: -0.10436203 | D41: -0.22546929 | E41: 3.2261367 | F41: 3.1494515 | G41: =AVERAGE(E41:F41) -> 3.1877941 | H41: =G41*2.35 -> 7.4913161 | I41: 0 | J41: 1

Sheet G1_GA90
A1: Gantry 1 Gantry angle 90
A2: T:\Routine QA\Annual Checks\G1\2023\Profiles\GA90\Fits_G90_RS0_Dist0_2023.xlsx
B4: Single Gaussian Fit
A5: Energy | B5: amplitude | C5: x_mean | D5: y_mean | E5: x_stddev | F5: y_stddev | G5: ave_stddev | H5: ave_fwhm | I5: theta | J5: amplitude
A6: 70 | B6: 1 | C6: 0.37343906 | D6: 0.3635012 | E6: 5.9861431 | F6: 5.8470189 | G6: =AVERAGE(E6:F6) -> 5.916581 | H6: =2.35*G6 -> 13.903965 | I6: 0 | J6: 0.98810836
A7: 75 | B7: 1 | C7: 0.28226071 | D7: 0.52937549 | E7: 5.7063933 | F7: 5.5207374 | G7: =AVERAGE(E7:F7) -> 5.6135654 | H7: =2.35*G7 -> 13.191879 | I7: 0 | J7: 0.99437868
A8: 80 | B8: 1 | C8: 0.059786505 | D8: 0.45642109 | E8: 5.4949618 | F8: 5.2965221 | G8: =AVERAGE(E8:F8) -> 5.3957419 | H8: =2.35*G8 -> 12.679994 | I8: 0 | J8: 0.88983938
A9: 85 | B9: 1 | C9: 0.082371735 | D9: 0.027352208 | E9: 5.2425694 | F9: 5.0472269 | G9: =AVERAGE(E9:F9) -> 5.1448981 | H9: =2.35*G9 -> 12.090511 | I9: 0 | J9: 0.89287116
A10: 90 | B10: 1 | C10: 0.082781315 | D10: 0.53339225 | E10: 5.1495374 | F10: 4.9603058 | G10: =AVERAGE(E10:F10) -> 5.0549216 | H10: =2.35*G10 -> 11.879066 | I10: 0 | J10: 0.88524927
A11: 95 | B11: 1 | C11: 0.28075359 | D11: 0.1072147 | E11: 5.0270891 | F11: 4.8656555 | G11: =AVERAGE(E11:F11) -> 4.9463723 | H11: =2.35*G11 -> 11.623975 | I11: 0 | J11: 1
A12: 100 | B12: 1 | C12: 0.016067831 | D12: -0.041156623 | E12: 4.818874 | F12: 4.6771214 | G12: =AVERAGE(E12:F12) -> 4.7479977 | H12: =2.35*G12 -> 11.157795 | I12: 0 | J12: 0.90681587
A13: 105 | B13: 1 | C13: 0.068781234 | D13: 0.33712831 | E13: 4.7525717 | F13: 4.6294281 | G13: =AVERAGE(E13:F13) -> 4.6909999 | H13: =2.35*G13 -> 11.02385 | I13: 0 | J13: 0.9112549
A14: 110 | B14: 1 | C14: 0.28301939 | D14: 0.34067517 | E14: 4.6356054 | F14: 4.5312316 | G14: =AVERAGE(E14:F14) -> 4.5834185 | H14: =2.35*G14 -> 10.771033 | I14: 0 | J14: 0.88511028
A15: 115 | B15: 1 | C15: 0.38879468 | D15: 0.51964216 | E15: 4.4830045 | F15: 4.3937522 | G15: =AVERAGE(E15:F15) -> 4.4383783 | H15: =2.35*G15 -> 10.430189 | I15: 0 | J15: 0.88359948
A16: 120 | B16: 1 | C16: 0.31879875 | D16: 0.25527847 | E16: 4.4236379 | F16: 4.3633653 | G16: =AVERAGE(E16:F16) -> 4.3935016 | H16: =2.35*G16 -> 10.324729 | I16: 0 | J16: 0.90425719
A17: 125 | B17: 1 | C17: -0.021554732 | D17: -0.10358256 | E17: 4.3013137 | F17: 4.2732836 | G17: =AVERAGE(E17:F17) -> 4.2872986 | H17: =2.35*G17 -> 10.075152 | I17: 0 | J17: 0.90043539
... A41: 245 | B41: 1 | C41: 0.17788788 | D41: 0.051053504 | E41: 3.1520957 | F41: 3.0011028 | G41: =AVERAGE(E41:F41) -> 3.0765993 | H41: =2.35*G41 -> 7.2300083 | I41: 0 | J41: 1

Sheet G1_GA180
A1: Gantry 1 Gantry angle 180
A2: T:\Routine QA\Annual Checks\G1\2023\Profiles\GA180\Fits_G180_RS0_Dist0_2023.xlsx
B4: Single Gaussian Fit
A5: Energy | B5: amplitude | C5: x_mean | D5: y_mean | E5: x_stddev | F5: y_stddev | G5: ave_stddev | H5: ave_fwhm | I5: theta | J5: amplitude
A6: 70 | B6: 1 | C6: 0.16689271 | D6: 0.64914431 | E6: 5.9488527 | F6: 5.8943754 | G6: =AVERAGE(E6:F6) -> 5.921614 | H6: =2.35*G6 -> 13.915793 | I6: 0 | J6: 0.986189
A7: 75 | B7: 1 | C7: 0.18347212 | D7: 0.35155715 | E7: 5.657617 | F7: 5.6336809 | G7: =AVERAGE(E7:F7) -> 5.645649 | H7: =2.35*G7 -> 13.267275 | I7: 0 | J7: 0.91521114
A8: 80 | B8: 1 | C8: 0.15736272 | D8: 0.29541113 | E8: 5.4018536 | F8: 5.3842183 | G8: =AVERAGE(E8:F8) -> 5.3930359 | H8: =2.35*G8 -> 12.673634 | I8: 0 | J8: 0.88919411
A9: 85 | B9: 1 | C9: -0.045031246 | D9: 0.41810922 | E9: 5.2194431 | F9: 5.1961343 | G9: =AVERAGE(E9:F9) -> 5.2077887 | H9: =2.35*G9 -> 12.238303 | I9: 0 | J9: 0.88474006
A10: 90 | B10: 1 | C10: 0.26000079 | D10: 0.13207133 | E10: 5.1168455 | F10: 5.0891626 | G10: =AVERAGE(E10:F10) -> 5.103004 | H10: =2.35*G10 -> 11.99206 | I10: 0 | J10: 0.88255112
A11: 95 | B11: 1 | C11: 0.23737598 | D11: 0.55016685 | E11: 4.9533843 | F11: 4.9143429 | G11: =AVERAGE(E11:F11) -> 4.9338636 | H11: =2.35*G11 -> 11.594579 | I11: 0 | J11: 0.83711
A12: 100 | B12: 1 | C12: 0.2037509 | D12: 0.33208327 | E12: 4.8638958 | F12: 4.8100315 | G12: =AVERAGE(E12:F12) -> 4.8369636 | H12: =2.35*G12 -> 11.366865 | I12: 0 | J12: 0.84366257
A13: 105 | B13: 1 | C13: -0.069472164 | D13: 0.036825907 | E13: 4.7653433 | F13: 4.7098879 | G13: =AVERAGE(E13:F13) -> 4.7376156 | H13: =2.35*G13 -> 11.133397 | I13: 0 | J13: 0.86475393
A14: 110 | B14: 1 | C14: 0.14799319 | D14: 0.35652013 | E14: 4.5719269 | F14: 4.5078794 | G14: =AVERAGE(E14:F14) -> 4.5399032 | H14: =2.35*G14 -> 10.668772 | I14: 0 | J14: 0.89552578
A15: 115 | B15: 1 | C15: 0.1949288 | D15: 0.23118951 | E15: 4.5637868 | F15: 4.4927991 | G15: =AVERAGE(E15:F15) -> 4.5282929 | H15: =2.35*G15 -> 10.641488 | I15: 0 | J15: 0.90872489
A16: 120 | B16: 1 | C16: 0.17646641 | D16: 0.23646731 | E16: 4.4686651 | F16: 4.3846522 | G16: =AVERAGE(E16:F16) -> 4.4266586 | H16: =2.35*G16 -> 10.402648 | I16: 0 | J16: 0.87629311
A17: 125 | B17: 1 | C17: -0.14777256 | D17: 0.091964243 | E17: 4.3714252 | F17: 4.2679064 | G17: =AVERAGE(E17:F17) -> 4.3196658 | H17: =2.35*G17 -> 10.151215 | I17: 0 | J17: 0.91241319
... A41: 245 | B41: 1 | C41: 0.080156697 | D41: -0.077907589 | E41: 3.2987531 | F41: 3.2531881 | G41: =AVERAGE(E41:F41) -> 3.2759706 | H41: =2.35*G41 -> 7.6985309 | I41: 0 | J41: 1

Sheet G1_GA270
A1: Gantry 1 GA270
A2: T:\Routine QA\Annual Checks\G1\2023\Profiles\GA270\Fits_G270_RS0_Dist0_2023.xlsx
B4: Single Gaussian Fit
A5: Energy | B5: amplitude | C5: x_mean | D5: y_mean | E5: x_stddev | F5: y_stddev | G5: ave_stddev | H5: ave_fwhm | I5: theta | J5: amplitude
A6: 70 | B6: 1 | C6: 0.40409429 | D6: 0.65825569 | E6: 5.8928374 | F6: 5.9926241 | G6: =AVERAGE(E6:F6) -> 5.9427308 | H6: =2.35*G6 -> 13.965417 | I6: 0 | J6: 0.99443154
A7: 75 | B7: 1 | C7: 0.14650047 | D7: 0.45130897 | E7: 5.6088313 | F7: 5.715061 | G7: =AVERAGE(E7:F7) -> 5.6619461 | H7: =2.35*G7 -> 13.305573 | I7: 0 | J7: 0.91219661
A8: 80 | B8: 1 | C8: -0.066346535 | D8: -0.0012069913 | E8: 5.3612797 | F8: 5.4794297 | G8: =AVERAGE(E8:F8) -> 5.4203547 | H8: =2.35*G8 -> 12.737834 | I8: 0 | J8: 0.9218408
A9: 85 | B9: 1 | C9: 0.10419784 | D9: 0.18503541 | E9: 5.1174231 | F9: 5.2331505 | G9: =AVERAGE(E9:F9) -> 5.1752868 | H9: =2.35*G9 -> 12.161924 | I9: 0 | J9: 0.89653414
A10: 90 | B10: 1 | C10: 0.45285545 | D10: 0.49129659 | E10: 4.9756407 | F10: 5.0959866 | G10: =AVERAGE(E10:F10) -> 5.0358137 | H10: =2.35*G10 -> 11.834162 | I10: 0 | J10: 0.88810184
A11: 95 | B11: 1 | C11: 0.17751297 | D11: 0.31566802 | E11: 4.8833937 | F11: 5.0208084 | G11: =AVERAGE(E11:F11) -> 4.952101 | H11: =2.35*G11 -> 11.637437 | I11: 0 | J11: 0.84265593
A12: 100 | B12: 1 | C12: 0.38480093 | D12: 0.61513338 | E12: 4.7343611 | F12: 4.8765597 | G12: =AVERAGE(E12:F12) -> 4.8054604 | H12: =2.35*G12 -> 11.292832 | I12: 0 | J12: 0.86358194
A13: 105 | B13: 1 | C13: 0.099678779 | D13: 0.31854811 | E13: 4.656769 | F13: 4.8205985 | G13: =AVERAGE(E13:F13) -> 4.7386838 | H13: =2.35*G13 -> 11.135907 | I13: 0 | J13: 0.92133889
A14: 110 | B14: 1 | C14: 0.08972678 | D14: 0.25079108 | E14: 4.4528737 | F14: 4.6322703 | G14: =AVERAGE(E14:F14) -> 4.542572 | H14: =2.35*G14 -> 10.675044 | I14: 0 | J14: 0.92411597
A15: 115 | B15: 1 | C15: 0.055663643 | D15: 0.42425458 | E15: 4.3526934 | F15: 4.5770756 | G15: =AVERAGE(E15:F15) -> 4.4648845 | H15: =2.35*G15 -> 10.492479 | I15: 0 | J15: 0.94050634
A16: 120 | B16: 1 | C16: 0.321485 | D16: 0.43144826 | E16: 4.253247 | F16: 4.5143767 | G16: =AVERAGE(E16:F16) -> 4.3838118 | H16: =2.35*G16 -> 10.301958 | I16: 0 | J16: 0.88805894
A17: 125 | B17: 1 | C17: 0.039925143 | D17: 0.13364526 | E17: 4.1592973 | F17: 4.4631193 | G17: =AVERAGE(E17:F17) -> 4.3112083 | H17: =2.35*G17 -> 10.131339 | I17: 0 | J17: 0.90208865
... A41: 245 | B41: 1 | C41: 0.22418551 | D41: -0.22778895 | E41: 3.3418274 | F41: 3.4600276 | G41: =AVERAGE(E41:F41) -> 3.4009275 | H41: =2.35*G41 -> 7.9921797 | I41: 0 | J41: 1

Sheet G2_GA0
A1: Gantry 2 GA0 commissioning data
A2: C:\Users\KAWCHUNG\NHS\(Canc) Radiotherapy - PBT Physics Team - PBT Physics Team\QAandCommissioning\Gantry 2\Commissioning\Profiles\Data\20210604 0607 GA0 analysis\Fits_G0_RS0_Dist0.xlsx
B4: Single Gaussian Fit
A5: Energy | B5: amplitude | C5: x_mean | D5: y_mean | E5: x_stddev | F5: y_stddev | G5: ave_stddev | H5: theta | I5: amplitude
A6: 70 | B6: 1 | C6: 0.44936389 | D6: 0.80259478 | E6: 6.1822928 | F6: 5.9363587 | G6: =AVERAGE(E6:F6) -> 6.0593258 | H6: 0 | I6: 0.89751044
A7: 75 | B7: 1 | C7: 0.52911772 | D7: 0.91595637 | E7: 5.8951914 | F7: 5.7328777 | G7: =AVERAGE(E7:F7) -> 5.8140346 | H7: 0 | I7: 0.913528
A8: 80 | B8: 1 | C8: 0.2355669 | D8: 0.47216503 | E8: 5.599868 | F8: 5.4969482 | G8: =AVERAGE(E8:F8) -> 5.5484081 | H8: 0 | I8: 0.89928389
A9: 85 | B9: 1 | C9: 0.18546075 | D9: 0.31385119 | E9: 5.3961201 | F9: 5.3048447 | G9: =AVERAGE(E9:F9) -> 5.3504824 | H9: 0 | I9: 0.95976387
A10: 90 | B10: 1 | C10: 0.1731925 | D10: 0.53494273 | E10: 5.2920328 | F10: 5.1747788 | G10: =AVERAGE(E10:F10) -> 5.2334058 | H10: 0 | I10: 0.90178954
A11: 95 | B11: 1 | C11: -0.051513558 | D11: 0.26071981 | E11: 5.0782631 | F11: 4.9274657 | G11: =AVERAGE(E11:F11) -> 5.0028644 | H11: 0 | I11: 0.84643321
A12: 100 | B12: 1 | C12: 0.011870257 | D12: 0.35938167 | E12: 5.0232421 | F12: 4.8275263 | G12: =AVERAGE(E12:F12) -> 4.9253842 | H12: 0 | I12: 0.98899076
A13: 105 | B13: 1 | C13: 0.25420698 | D13: 0.19398406 | E13: 4.8533795 | F13: 4.6167637 | G13: =AVERAGE(E13:F13) -> 4.7350716 | H13: 0 | I13: 0.87101544
A14: 110 | B14: 1 | C14: 0.1910399 | D14: 0.38502682 | E14: 4.8480108 | F14: 4.5630769 | G14: =AVERAGE(E14:F14) -> 4.7055438 | H14: 0 | I14: 0.99507417
A15: 115 | B15: 1 | C15: 0.41119337 | D15: 0.27021329 | E15: 4.7344209 | F15: 4.4149625 | G15: =AVERAGE(E15:F15) -> 4.5746917 | H15: 0 | I15: 0.99289985
A16: 120 | B16: 1 | C16: 0.23942801 | D16: 0.30714313 | E16: 4.6603773 | F16: 4.3285001 | G16: =AVERAGE(E16:F16) -> 4.4944387 | H16: 0 | I16: 0.99532588
A17: 125 | B17: 1 | C17: 0.28619964 | D17: 0.44838629 | E17: 4.5847186 | F17: 4.238925 | G17: =AVERAGE(E17:F17) -> 4.4118218 | H17: 0 | I17: 0.89894637
... A41: 245 | B41: 1 | C41: 0.14792986 | D41: 0.084975735 | E41: 3.274918 | F41: 3.2261503 | G41: =AVERAGE(E41:F41) -> 3.2505342 | H41: 0 | I41: 1

Sheet G2_GA0_annual
A1: Gantry 2 GA0 annual data
A2: T:\Routine QA\Annual Checks\G2\2022\Profiles\Acquired Profiles\Fits_G0_RS0_Dist0.xlsx
B4: Single Gaussian Fit
A5: Energy | B5: amplitude | C5: x_mean | D5: y_mean | E5: x_stddev | F5: y_stddev | G5: ave_stddev | H5: ave_fwhm | I5: theta | J5: amplitude
A6: 70 | B6: 1 | C6: 0.084284847 | D6: -0.081430621 | E6: 6.1954539 | F6: 5.9147844 | G6: =AVERAGE(E6:F6) -> 6.0551192 | H6: =2.35*G6 -> 14.22953 | I6: 0 | J6: 0.97637473
A7: 75 | B7: 1 | C7: 0.21112893 | D7: 0.03737464 | E7: 5.889116 | F7: 5.7086693 | G7: =AVERAGE(E7:F7) -> 5.7988927 | H7: =2.35*G7 -> 13.627398 | I7: 0 | J7: 0.98712732
A8: 80 | B8: 1 | C8: 0.1929301 | D8: -0.13808672 | E8: 5.6312451 | F8: 5.5321933 | G8: =AVERAGE(E8:F8) -> 5.5817192 | H8: =2.35*G8 -> 13.11704 | I8: 0 | J8: 0.99127855
A9: 85 | B9: 1 | C9: 0.16239459 | D9: -0.024327375 | E9: 5.3748972 | F9: 5.2976402 | G9: =AVERAGE(E9:F9) -> 5.3362687 | H9: =2.35*G9 -> 12.540231 | I9: 0 | J9: 0.98827409
A10: 90 | B10: 1 | C10: 0.17525715 | D10: -0.11691316 | E10: 5.2329548 | F10: 5.1361986 | G10: =AVERAGE(E10:F10) -> 5.1845767 | H10: =2.35*G10 -> 12.183755 | I10: 0 | J10: 0.99323205
A11: 95 | B11: 1 | C11: 0.10347878 | D11: 0.14019453 | E11: 5.12018 | F11: 4.9704114 | G11: =AVERAGE(E11:F11) -> 5.0452957 | H11: =2.35*G11 -> 11.856445 | I11: 0 | J11: 0.99111467
A12: 100 | B12: 1 | C12: 0.0098822828 | D12: 0.17408521 | E12: 4.9743421 | F12: 4.7851137 | G12: =AVERAGE(E12:F12) -> 4.8797279 | H12: =2.35*G12 -> 11.467361 | I12: 0 | J12: 0.99397724
A13: 105 | B13: 1 | C13: 0.10790879 | D13: 0.11477595 | E13: 4.8973736 | F13: 4.6680513 | G13: =AVERAGE(E13:F13) -> 4.7827124 | H13: =2.35*G13 -> 11.239374 | I13: 0 | J13: 0.99411417
A14: 110 | B14: 1 | C14: -0.023417569 | D14: 0.019515305 | E14: 4.8289351 | F14: 4.5540485 | G14: =AVERAGE(E14:F14) -> 4.6914918 | H14: =2.35*G14 -> 11.025006 | I14: 0 | J14: 0.99722819
A15: 115 | B15: 0.99427151 | C15: 0.11761889 | D15: 0.14568565 | E15: 4.7155667 | F15: 4.4088991 | G15: =AVERAGE(E15:F15) -> 4.5622329 | H15: =2.35*G15 -> 10.721247 | I15: 0 | J15: 0.99402882
A16: 120 | B16: 1 | C16: 0.11939528 | D16: 0.14124227 | E16: 4.6451616 | F16: 4.3192662 | G16: =AVERAGE(E16:F16) -> 4.4822139 | H16: =2.35*G16 -> 10.533203 | I16: 0 | J16: 0.87678348
A17: 125 | B17: 1 | C17: -0.057531314 | D17: 0.095893568 | E17: 4.5803116 | F17: 4.2461614 | G17: =AVERAGE(E17:F17) -> 4.4132365 | H17: =2.35*G17 -> 10.371106 | I17: 0 | J17: 0.99794814
... A41: 245 | B41: 1 | C41: 0.18097524 | D41: 0.15277676 | E41: 3.2710899 | F41: 3.2844048 | G41: =AVERAGE(E41:F41) -> 3.2777474 | H41: =2.35*G41 -> 7.7027063 | I41: 0 | J41: 1

Sheet G2_GA90
A1: Gantry 2 GA90 annual QA data
A2: T:\Routine QA\Annual Checks\G2\2022\Profiles\Acquired Profiles\Fits_G90_RS0_Dist0.xlsx
B4: Single Gaussian Fit
A5: Energy | B5: amplitude | C5: x_mean | D5: y_mean | E5: x_stddev | F5: y_stddev | G5: ave_stddev | H5: ave_fwhm | I5: theta | J5: amplitude
A6: 70 | B6: 0.98606438 | C6: -0.028174481 | D6: 0.11117525 | E6: 6.0504637 | F6: 6.0959191 | G6: =AVERAGE(E6:F6) -> 6.0731914 | H6: =2.35*G6 -> 14.272 | I6: 0 | J6: 0.98025401
A7: 75 | B7: 1 | C7: 0.045457293 | D7: 0.019527358 | E7: 5.8313211 | F7: 5.6287875 | G7: =AVERAGE(E7:F7) -> 5.7300543 | H7: =2.35*G7 -> 13.465628 | I7: 0 | J7: 0.97200102
A8: 80 | B8: 1 | C8: 0.20328304 | D8: 0.16208207 | E8: 5.691296 | F8: 5.3861751 | G8: =AVERAGE(E8:F8) -> 5.5387355 | H8: =2.35*G8 -> 13.016029 | I8: 0 | J8: 0.9885378
A9: 85 | B9: 1 | C9: 0.06263305 | D9: -0.088921188 | E9: 5.4956927 | F9: 5.1709521 | G9: =AVERAGE(E9:F9) -> 5.3333224 | H9: =2.35*G9 -> 12.533308 | I9: 0 | J9: 0.98898298
A10: 90 | B10: 1 | C10: -0.062131106 | D10: -0.042162752 | E10: 5.3171241 | F10: 5.0381755 | G10: =AVERAGE(E10:F10) -> 5.1776498 | H10: =2.35*G10 -> 12.167477 | I10: 0 | J10: 0.98611603
A11: 95 | B11: 1 | C11: -0.081730478 | D11: 0.029360337 | E11: 5.1290931 | F11: 4.913973 | G11: =AVERAGE(E11:F11) -> 5.021533 | H11: =2.35*G11 -> 11.800603 | I11: 0 | J11: 0.98671765
A12: 100 | B12: 1 | C12: 0.053826242 | D12: 0.063000572 | E12: 4.955598 | F12: 4.8157572 | G12: =AVERAGE(E12:F12) -> 4.8856776 | H12: =2.35*G12 -> 11.481342 | I12: 0 | J12: 0.99103199
A13: 105 | B13: 1 | C13: 0.057481769 | D13: 0.018890364 | E13: 4.7625794 | F13: 4.6978139 | G13: =AVERAGE(E13:F13) -> 4.7301966 | H13: =2.35*G13 -> 11.115962 | I13: 0 | J13: 0.99389262
A14: 110 | B14: 0.99928482 | C14: 0.037102005 | D14: 0.099798475 | E14: 4.6208056 | F14: 4.6258533 | G14: =AVERAGE(E14:F14) -> 4.6233294 | H14: =2.35*G14 -> 10.864824 | I14: 0 | J14: 0.99502061
A15: 115 | B15: 1 | C15: -0.20532746 | D15: 0.05579305 | E15: 4.4836311 | F15: 4.5375882 | G15: =AVERAGE(E15:F15) -> 4.5106097 | H15: =2.35*G15 -> 10.599933 | I15: 0 | J15: 0.99606872
A16: 120 | B16: 1 | C16: 0.052801459 | D16: -0.059690643 | E16: 4.3790039 | F16: 4.4742598 | G16: =AVERAGE(E16:F16) -> 4.4266319 | H16: =2.35*G16 -> 10.402585 | I16: 0 | J16: 0.99742695
A17: 125 | B17: 1 | C17: 0.019454715 | D17: 0.052679494 | E17: 4.2832795 | F17: 4.3843412 | G17: =AVERAGE(E17:F17) -> 4.3338104 | H17: =2.35*G17 -> 10.184454 | I17: 0 | J17: 0.99675012
... A41: 245 | B41: 1 | C41: -0.089173515 | D41: 0.082425011 | E41: 3.1059227 | F41: 2.7229645 | G41: =AVERAGE(E41:F41) -> 2.9144436 | H41: =2.35*G41 -> 6.8489424 | I41: 0 | J41: 0.99376676

Sheet G2_GA180
A1: Gantry 2 GA180 annual QA data
A2: T:\Routine QA\Annual Checks\G2\2022\Profiles\Acquired Profiles\Fits_G180_RS0_Dist0.xlsx
B4: Single Gaussian Fit
A5: Energy | B5: amplitude | C5: x_mean | D5: y_mean | E5: x_stddev | F5: y_stddev | G5: ave_stddev | H5: ave_fwhm | I5: theta | J5: amplitude
A6: 70 | B6: 1 | C6: -0.015060515 | D6: -0.030281139 | E6: 6.2561206 | F6: 6.0093631 | G6: =AVERAGE(E6:F6) -> 6.1327418 | H6: =2.35*G6 -> 14.411943 | I6: 0 | J6: 0.98179052
A7: 75 | B7: 1 | C7: -0.024351614 | D7: 0.080341704 | E7: 5.905682 | F7: 5.7754568 | G7: =AVERAGE(E7:F7) -> 5.8405694 | H7: =2.35*G7 -> 13.725338 | I7: 0 | J7: 0.98342408
A8: 80 | B8: 1 | C8: 0.074264634 | D8: -0.12360655 | E8: 5.5838745 | F8: 5.5449824 | G8: =AVERAGE(E8:F8) -> 5.5644285 | H8: =2.35*G8 -> 13.076407 | I8: 0 | J8: 0.98263256
A9: 85 | B9: 1 | C9: -0.12440678 | D9: 0.1228614 | E9: 5.4146946 | F9: 5.3964506 | G9: =AVERAGE(E9:F9) -> 5.4055726 | H9: =2.35*G9 -> 12.703096 | I9: 0 | J9: 0.98529303
A10: 90 | B10: 1 | C10: -0.011392216 | D10: 0.098762037 | E10: 5.2572794 | F10: 5.2149228 | G10: =AVERAGE(E10:F10) -> 5.2361011 | H10: =2.35*G10 -> 12.304838 | I10: 0 | J10: 0.98789003
A11: 95 | B11: 1 | C11: -0.052037837 | D11: -0.057649152 | E11: 5.0821356 | F11: 4.9975507 | G11: =AVERAGE(E11:F11) -> 5.0398431 | H11: =2.35*G11 -> 11.843631 | I11: 0 | J11: 0.98783934
A12: 100 | B12: 1 | C12: -0.041597865 | D12: -0.068949932 | E12: 4.984963 | F12: 4.8478556 | G12: =AVERAGE(E12:F12) -> 4.9164093 | H12: =2.35*G12 -> 11.553562 | I12: 0 | J12: 0.7
A13: 105 | B13: 1 | C13: 0.001042957 | D13: 0.031035297 | E13: 4.8690478 | F13: 4.6940924 | G13: =AVERAGE(E13:F13) -> 4.7815701 | H13: =2.35*G13 -> 11.23669 | I13: 0 | J13: 0.9898733
A14: 110 | B14: 1 | C14: -0.21177505 | D14: -0.12063148 | E14: 4.7689272 | F14: 4.556618 | G14: =AVERAGE(E14:F14) -> 4.6627726 | H14: =2.35*G14 -> 10.957516 | I14: 0 | J14: 0.99098218
A15: 115 | B15: 1 | C15: -0.12376502 | D15: 0.11478686 | E15: 4.6757281 | F15: 4.4321131 | G15: =AVERAGE(E15:F15) -> 4.5539206 | H15: =2.35*G15 -> 10.701713 | I15: 0 | J15: 0.99144165
A16: 120 | B16: 1 | C16: -0.23707035 | D16: -0.11615094 | E16: 4.5587064 | F16: 4.2865378 | G16: =AVERAGE(E16:F16) -> 4.4226221 | H16: =2.35*G16 -> 10.393162 | I16: 0 | J16: 0.99117529
A17: 125 | B17: 1 | C17: -0.18474085 | D17: -0.066164506 | E17: 4.5344187 | F17: 4.2557545 | G17: =AVERAGE(E17:F17) -> 4.3950866 | H17: =2.35*G17 -> 10.328454 | I17: 0 | J17: 0.99425778
... A41: 245 | B41: 1 | C41: 0.31073442 | D41: -0.0081306952 | E41: 3.2107836 | F41: 3.2843816 | G41: =AVERAGE(E41:F41) -> 3.2475826 | H41: =2.35*G41 -> 7.6318191 | I41: 0 | J41: 0.99979607

Sheet G2_GA270
A1: Gantry 2 GA270 annual QA data
A2: T:\Routine QA\Annual Checks\G2\2022\Profiles\Acquired Profiles\Fits_G270_RS0_Dist0.xlsx
B4: Single Gaussian Fit
A5: Energy | B5: amplitude | C5: x_mean | D5: y_mean | E5: x_stddev | F5: y_stddev | G5: ave_stddev | H5: ave-fwhm | I5: theta | J5: amplitude
A6: 70 | B6: 1 | C6: 0.051528581 | D6: 0.14453102 | E6: 6.0930791 | F6: 6.1338419 | G6: =AVERAGE(E6:F6) -> 6.1134605 | H6: =2.35*G6 -> 14.366632 | I6: 0 | J6: 0.98287889
A7: 75 | B7: 1 | C7: -0.082913846 | D7: -0.092701624 | E7: 5.897999 | F7: 5.7785037 | G7: =AVERAGE(E7:F7) -> 5.8382513 | H7: =2.35*G7 -> 13.719891 | I7: 0 | J7: 0.97952371
A8: 80 | B8: 1 | C8: -0.27521055 | D8: 0.03932905 | E8: 5.7445578 | F8: 5.5044929 | G8: =AVERAGE(E8:F8) -> 5.6245254 | H8: =2.35*G8 -> 13.217635 | I8: 0 | J8: 0.98818482
A9: 85 | B9: 1 | C9: -0.095746619 | D9: -0.049403193 | E9: 5.5974537 | F9: 5.3229165 | G9: =AVERAGE(E9:F9) -> 5.4601851 | H9: =2.35*G9 -> 12.831435 | I9: 0 | J9: 0.98828621
A10: 90 | B10: 1 | C10: -0.059294706 | D10: -0.0099613602 | E10: 5.3774313 | F10: 5.1294906 | G10: =AVERAGE(E10:F10) -> 5.2534609 | H10: =2.35*G10 -> 12.345633 | I10: 0 | J10: 0.98403434
A11: 95 | B11: 1 | C11: -0.17501642 | D11: 0.09179914 | E11: 5.2064867 | F11: 5.0247882 | G11: =AVERAGE(E11:F11) -> 5.1156374 | H11: =2.35*G11 -> 12.021748 | I11: 0 | J11: 0.99206405
A12: 100 | B12: 1 | C12: 0.00048742109 | D12: 0.044107146 | E12: 5.0281885 | F12: 4.8984632 | G12: =AVERAGE(E12:F12) -> 4.9633259 | H12: =2.35*G12 -> 11.663816 | I12: 0 | J12: 0.99016247
A13: 105 | B13: 1 | C13: -0.1639508 | D13: 0.0056185904 | E13: 4.8723461 | F13: 4.7993023 | G13: =AVERAGE(E13:F13) -> 4.8358242 | H13: =2.35*G13 -> 11.364187 | I13: 0 | J13: 0.7
A14: 110 | B14: 1 | C14: -0.21431405 | D14: 0.12516384 | E14: 4.7415586 | F14: 4.7266874 | G14: =AVERAGE(E14:F14) -> 4.734123 | H14: =2.35*G14 -> 11.125189 | I14: 0 | J14: 0.99682664
A15: 115 | B15: 1 | C15: -0.01632662 | D15: -0.060022961 | E15: 4.569822 | F15: 4.6150505 | G15: =AVERAGE(E15:F15) -> 4.5924363 | H15: =2.35*G15 -> 10.792225 | I15: 0 | J15: 0.99526091
A16: 120 | B16: 0.98944624 | C16: -0.065342143 | D16: 0.055332685 | E16: 4.4288984 | F16: 4.5239111 | G16: =AVERAGE(E16:F16) -> 4.4764047 | H16: =2.35*G16 -> 10.519551 | I16: 0 | J16: 0.99271119
A17: 125 | B17: 1 | C17: -0.21122805 | D17: 0.067537207 | E17: 4.3317525 | F17: 4.4571808 | G17: =AVERAGE(E17:F17) -> 4.3944667 | H17: =2.35*G17 -> 10.326997 | I17: 0 | J17: 0.99672412
... A41: 245 | B41: 1 | C41: 0.05995235 | D41: 0.11112008 | E41: 3.0085604 | F41: 2.8101478 | G41: =AVERAGE(E41:F41) -> 2.9093541 | H41: =2.35*G41 -> 6.8369821 | I41: 0 | J41: 0.99030397

Sheet G3_GA0
A1: Gantry 3 commissioning data
A2: C:\Users\KAWCHUNG\NHS\(Canc) Radiotherapy - PBT Physics Team - PBT Physics Team\QAandCommissioning\Gantry 3\Commissioning\Profiles\_G3 COMM PROFILES\Results_2021-12-02_4000\Fits_G0_RS0_Dist0.xlsx
B4: Single Gaussian Fit
A5: Energy | B5: amplitude | C5: x_mean | D5: y_mean | E5: x_stddev | F5: y_stddev | G5: ave_stddev | H5: ave_fwhm | I5: theta | J5: amplitude
A6: 70 | B6: 1 | C6: 0.40947696 | D6: 0.65358475 | E6: 6.0380541 | F6: 5.9474503 | G6: =AVERAGE(E6:F6) -> 5.9927522 | H6: =2.35*G6 -> 14.082968 | I6: 0 | J6: 0.89758915
A7: 75 | B7: 1 | C7: 0.0069835952 | D7: 0.69844374 | E7: 5.8613896 | F7: 5.818592 | G7: =AVERAGE(E7:F7) -> 5.8399908 | H7: =2.35*G7 -> 13.723978 | I7: 0 | J7: 0.91779251
A8: 80 | B8: 1 | C8: -0.18515968 | D8: 0.28879231 | E8: 5.5698654 | F8: 5.5834385 | G8: =AVERAGE(E8:F8) -> 5.5766519 | H8: =2.35*G8 -> 13.105132 | I8: 0 | J8: 0.95448714
A9: 85 | B9: 1 | C9: 0.17223268 | D9: 0.17043858 | E9: 5.4418278 | F9: 5.4651117 | G9: =AVERAGE(E9:F9) -> 5.4534697 | H9: =2.35*G9 -> 12.815654 | I9: 0 | J9: 0.98494942
A10: 90 | B10: 1 | C10: 0.074213667 | D10: 0.40645001 | E10: 5.2837359 | F10: 5.3139802 | G10: =AVERAGE(E10:F10) -> 5.298858 | H10: =2.35*G10 -> 12.452316 | I10: 0 | J10: 0.98834924
A11: 95 | B11: 1 | C11: 0.13858157 | D11: 0.65535548 | E11: 5.0710221 | F11: 5.0851803 | G11: =AVERAGE(E11:F11) -> 5.0781012 | H11: =2.35*G11 -> 11.933538 | I11: 0 | J11: 0.97783083
A12: 100 | B12: 1 | C12: -0.035571049 | D12: 0.39205459 | E12: 4.9265757 | F12: 4.9116191 | G12: =AVERAGE(E12:F12) -> 4.9190974 | H12: =2.35*G12 -> 11.559879 | I12: 0 | J12: 0.96943907
A13: 105 | B13: 1 | C13: 0.079999076 | D13: 0.27040175 | E13: 4.8618185 | F13: 4.7854602 | G13: =AVERAGE(E13:F13) -> 4.8236394 | H13: =2.35*G13 -> 11.335553 | I13: 0 | J13: 0.9895455
A14: 110 | B14: 1 | C14: 0.18623921 | D14: 0.65290471 | E14: 4.7114661 | F14: 4.610524 | G14: =AVERAGE(E14:F14) -> 4.660995 | H14: =2.35*G14 -> 10.953338 | I14: 0 | J14: 0.85245968
A15: 115 | B15: 1 | C15: -0.021789126 | D15: 0.12387959 | E15: 4.6688516 | F15: 4.5128974 | G15: =AVERAGE(E15:F15) -> 4.5908745 | H15: =2.35*G15 -> 10.788555 | I15: 0 | J15: 0.99496578
A16: 120 | B16: 1 | C16: 0.03142363 | D16: 0.2648568 | E16: 4.5621661 | F16: 4.3927457 | G16: =AVERAGE(E16:F16) -> 4.4774559 | H16: =2.35*G16 -> 10.522021 | I16: 0 | J16: 0.99565593
A17: 125 | B17: 1 | C17: -0.11844907 | D17: 0.11986177 | E17: 4.494083 | F17: 4.3037412 | G17: =AVERAGE(E17:F17) -> 4.3989121 | H17: =2.35*G17 -> 10.337443 | I17: 0 | J17: 0.99751089
... A41: 245 | B41: 1 | C41: -0.14398089 | D41: 0.39329914 | E41: 3.077466 | F41: 2.9868856 | G41: =AVERAGE(E41:F41) -> 3.0321758 | H41: =2.35*G41 -> 7.1256132 | I41: 0 | J41: 0.99912934

Sheet G3_GA90
A1: Gantry 3 commissioning data
A2: C:\Users\KAWCHUNG\NHS\(Canc) Radiotherapy - PBT Physics Team - PBT Physics Team\QAandCommissioning\Gantry 3\Commissioning\Profiles\_G3 COMM PROFILES\Results_2021-12-15_4000\Fits_G90_RS0_Dist0.xlsx
B4: Single Gaussian Fit
A5: Energy | B5: amplitude | C5: x_mean | D5: y_mean | E5: x_stddev | F5: y_stddev | G5: ave_stddev | H5: ave_fwhm | I5: theta | J5: amplitude
A6: 70 | B6: 1 | C6: 0.40544107 | D6: 0.66506995 | E6: 5.9227154 | F6: 6.0049905 | G6: =AVERAGE(E6:F6) -> 5.963853 | H6: =2.35*G6 -> 14.015054 | I6: 0 | J6: 0.90209305
A7: 75 | B7: 1 | C7: 0.17584519 | D7: 0.36733185 | E7: 5.8201088 | F7: 5.7969472 | G7: =AVERAGE(E7:F7) -> 5.808528 | H7: =2.35*G7 -> 13.650041 | I7: 0 | J7: 0.90075234
A8: 80 | B8: 1 | C8: 0.41616191 | D8: 0.65454273 | E8: 5.6780467 | F8: 5.5559689 | G8: =AVERAGE(E8:F8) -> 5.6170078 | H8: =2.35*G8 -> 13.199968 | I8: 0 | J8: 0.97582666
A9: 85 | B9: 1 | C9: -0.0093972486 | D9: 0.23141656 | E9: 5.5112398 | F9: 5.3481156 | G9: =AVERAGE(E9:F9) -> 5.4296777 | H9: =2.35*G9 -> 12.759743 | I9: 0 | J9: 0.89765867
A10: 90 | B10: 1 | C10: 0.050671931 | D10: 0.47774072 | E10: 5.3513852 | F10: 5.1737075 | G10: =AVERAGE(E10:F10) -> 5.2625463 | H10: =2.35*G10 -> 12.366984 | I10: 0 | J10: 0.97489664
A11: 95 | B11: 1 | C11: 0.25876592 | D11: 0.25655434 | E11: 5.167794 | F11: 5.0063382 | G11: =AVERAGE(E11:F11) -> 5.0870661 | H11: =2.35*G11 -> 11.954605 | I11: 0 | J11: 0.90409707
A12: 100 | B12: 1 | C12: 0.047839535 | D12: 0.011352321 | E12: 5.0581196 | F12: 4.9223107 | G12: =AVERAGE(E12:F12) -> 4.9902152 | H12: =2.35*G12 -> 11.727006 | I12: 0 | J12: 0.98800804
A13: 105 | B13: 1 | C13: 0.18695431 | D13: 0.28576635 | E13: 4.9055486 | F13: 4.809247 | G13: =AVERAGE(E13:F13) -> 4.8573978 | H13: =2.35*G13 -> 11.414885 | I13: 0 | J13: 0.834339
A14: 110 | B14: 1 | C14: 0.10843783 | D14: 0.14374457 | E14: 4.6372571 | F14: 4.5923237 | G14: =AVERAGE(E14:F14) -> 4.6147904 | H14: =2.35*G14 -> 10.844757 | I14: 0 | J14: 0.7
A15: 115 | B15: 1 | C15: 0.31741467 | D15: 0.34191843 | E15: 4.591085 | F15: 4.5609394 | G15: =AVERAGE(E15:F15) -> 4.5760122 | H15: =2.35*G15 -> 10.753629 | I15: 0 | J15: 0.99231317
A16: 120 | B16: 1 | C16: 0.059570561 | D16: 0.4152459 | E16: 4.5121118 | F16: 4.514645 | G16: =AVERAGE(E16:F16) -> 4.5133784 | H16: =2.35*G16 -> 10.606439 | I16: 0 | J16: 0.91558518
A17: 125 | B17: 1 | C17: 0.20867922 | D17: 0.34401042 | E17: 4.3934441 | F17: 4.4058826 | G17: =AVERAGE(E17:F17) -> 4.3996634 | H17: =2.35*G17 -> 10.339209 | I17: 0 | J17: 0.9971083
... A41: 245 | B41: 1 | C41: 0.0090575057 | D41: 0.064852743 | E41: 3.099681 | F41: 3.2371274 | G41: =AVERAGE(E41:F41) -> 3.1684042 | H41: =2.35*G41 -> 7.4457499 | I41: 0 | J41: 1

Sheet G3_GA180
A1: Gantry 3 commissioning data
A2: C:\Users\KAWCHUNG\NHS\(Canc) Radiotherapy - PBT Physics Team - PBT Physics Team\QAandCommissioning\Gantry 3\Commissioning\Profiles\_G3 COMM PROFILES\Results_2021-12-15_3000\Fits_G180_RS0_Dist0.xlsx
B4: Single Gaussian Fit
A5: Energy | B5: amplitude | C5: x_mean | D5: y_mean | E5: x_stddev | F5: y_stddev | G5: ave_stddev | H5: ave_fwhm | I5: theta | J5: amplitude
A6: 70 | B6: 1 | C6: 0.35563859 | D6: 0.63536644 | E6: 5.9309617 | F6: 6.0243297 | G6: =AVERAGE(E6:F6) -> 5.9776457 | H6: =2.35*G6 -> 14.047467 | I6: 0 | J6: 0.90689518
A7: 75 | B7: 1 | C7: 0.092167651 | D7: 0.33146162 | E7: 5.7041125 | F7: 5.7998228 | G7: =AVERAGE(E7:F7) -> 5.7519676 | H7: =2.35*G7 -> 13.517124 | I7: 0 | J7: 0.96546682
A8: 80 | B8: 1 | C8: -0.16022341 | D8: 0.19315552 | E8: 5.5436057 | F8: 5.5934313 | G8: =AVERAGE(E8:F8) -> 5.5685185 | H8: =2.35*G8 -> 13.086019 | I8: 0 | J8: 0.97744727
A9: 85 | B9: 1 | C9: 0.352056 | D9: 0.65676316 | E9: 5.3945341 | F9: 5.4327515 | G9: =AVERAGE(E9:F9) -> 5.4136428 | H9: =2.35*G9 -> 12.722061 | I9: 0 | J9: 0.91908479
A10: 90 | B10: 1 | C10: 0.40573709 | D10: 0.38591349 | E10: 5.2012404 | F10: 5.2506 | G10: =AVERAGE(E10:F10) -> 5.2259202 | H10: =2.35*G10 -> 12.280912 | I10: 0 | J10: 0.97951424
A11: 95 | B11: 1 | C11: -0.10116662 | D11: 0.55334183 | E11: 5.0448497 | F11: 5.1064874 | G11: =AVERAGE(E11:F11) -> 5.0756686 | H11: =2.35*G11 -> 11.927821 | I11: 0 | J11: 0.87209067
A12: 100 | B12: 1 | C12: 0.076595482 | D12: 0.2537143 | E12: 4.941336 | F12: 5.025322 | G12: =AVERAGE(E12:F12) -> 4.983329 | H12: =2.35*G12 -> 11.710823 | I12: 0 | J12: 0.99288031
A13: 105 | B13: 1 | C13: 0.10076708 | D13: 0.69469749 | E13: 4.7485548 | F13: 4.8671113 | G13: =AVERAGE(E13:F13) -> 4.807833 | H13: =2.35*G13 -> 11.298408 | I13: 0 | J13: 0.87413001
A14: 110 | B14: 1 | C14: -0.11134728 | D14: 0.0033152783 | E14: 4.6344174 | F14: 4.7907395 | G14: =AVERAGE(E14:F14) -> 4.7125785 | H14: =2.35*G14 -> 11.074559 | I14: 0 | J14: 0.99410922
A15: 115 | B15: 1 | C15: 0.12837277 | D15: 0.30238733 | E15: 4.4968764 | F15: 4.6745564 | G15: =AVERAGE(E15:F15) -> 4.5857164 | H15: =2.35*G15 -> 10.776433 | I15: 0 | J15: 0.99433923
A16: 120 | B16: 1 | C16: 0.099169299 | D16: 0.30403274 | E16: 4.3876187 | F16: 4.5914213 | G16: =AVERAGE(E16:F16) -> 4.48952 | H16: =2.35*G16 -> 10.550372 | I16: 0 | J16: 0.99607624
A17: 125 | B17: 1 | C17: 0.03215013 | D17: 0.48446087 | E17: 4.2711401 | F17: 4.4793161 | G17: =AVERAGE(E17:F17) -> 4.3752281 | H17: =2.35*G17 -> 10.281786 | I17: 0 | J17: 0.99475911
... A41: 245 | B41: 1 | C41: 0.071289121 | D41: 0.24502368 | E41: 2.9593507 | F41: 3.0595896 | G41: =AVERAGE(E41:F41) -> 3.0094702 | H41: =2.35*G41 -> 7.0722549 | I41: 0 | J41: 0.99590013

Sheet G3_GA270
A1: Gantry 3 commissioning data
A2: C:\Users\KAWCHUNG\NHS\(Canc) Radiotherapy - PBT Physics Team - PBT Physics Team\QAandCommissioning\Gantry 3\Commissioning\Profiles\_G3 COMM PROFILES\Results_2021-12-15_4000\Fits_G270_RS0_Dist0.xlsx
B4: Single Gaussian Fit
A5: Energy | B5: amplitude | C5: x_mean | D5: y_mean | E5: x_stddev | F5: y_stddev | G5: ave_stddev | H5: ave_fwhm | I5: theta | J5: amplitude
A6: 70 | B6: 1 | C6: 0.080950532 | D6: 0.56705734 | E6: 5.913573 | F6: 6.0003663 | G6: =AVERAGE(E6:F6) -> 5.9569697 | H6: =2.35*G6 -> 13.998879 | I6: 0 | J6: 0.90212421
A7: 75 | B7: 1 | C7: 0.15051665 | D7: 0.58342396 | E7: 5.8089246 | F7: 5.7961722 | G7: =AVERAGE(E7:F7) -> 5.8025484 | H7: =2.35*G7 -> 13.635989 | I7: 0 | J7: 0.91004038
A8: 80 | B8: 1 | C8: 0.13039118 | D8: 0.051703906 | E8: 5.6056779 | F8: 5.5157241 | G8: =AVERAGE(E8:F8) -> 5.560701 | H8: =2.35*G8 -> 13.067647 | I8: 0 | J8: 1
A9: 85 | B9: 1 | C9: -0.16435944 | D9: 0.79311007 | E9: 5.4948269 | F9: 5.3226884 | G9: =AVERAGE(E9:F9) -> 5.4087576 | H9: =2.35*G9 -> 12.71058 | I9: 0 | J9: 0.91440205
A10: 90 | B10: 1 | C10: 0.11746625 | D10: 0.61252449 | E10: 5.3899593 | F10: 5.2036617 | G10: =AVERAGE(E10:F10) -> 5.2968105 | H10: =2.35*G10 -> 12.447505 | I10: 0 | J10: 0.89573895
A11: 95 | B11: 1 | C11: 0.081393476 | D11: 0.36815003 | E11: 5.1983022 | F11: 5.0442319 | G11: =AVERAGE(E11:F11) -> 5.121267 | H11: =2.35*G11 -> 12.034978 | I11: 0 | J11: 0.8858271
A12: 100 | B12: 1 | C12: 0.13430785 | D12: 0.36635936 | E12: 5.0704182 | F12: 4.9405504 | G12: =AVERAGE(E12:F12) -> 5.0054843 | H12: =2.35*G12 -> 11.762888 | I12: 0 | J12: 0.8840963
A13: 105 | B13: 1 | C13: 0.24251566 | D13: 0.66414276 | E13: 4.898614 | F13: 4.8057615 | G13: =AVERAGE(E13:F13) -> 4.8521877 | H13: =2.35*G13 -> 11.402641 | I13: 0 | J13: 0.83016233
A14: 110 | B14: 1 | C14: -0.10450993 | D14: 0.36082999 | E14: 4.7943904 | F14: 4.7207389 | G14: =AVERAGE(E14:F14) -> 4.7575647 | H14: =2.35*G14 -> 11.180277 | I14: 0 | J14: 0.84811548
A15: 115 | B15: 1 | C15: -0.24929853 | D15: 0.1346985 | E15: 4.6266223 | F15: 4.5958406 | G15: =AVERAGE(E15:F15) -> 4.6112315 | H15: =2.35*G15 -> 10.836394 | I15: 0 | J15: 0.88174717
A16: 120 | B16: 1 | C16: -0.31406694 | D16: 0.12906997 | E16: 4.4932351 | F16: 4.4979397 | G16: =AVERAGE(E16:F16) -> 4.4955874 | H16: =2.35*G16 -> 10.56463 | I16: 0 | J16: 0.99730738
A17: 125 | B17: 1 | C17: -0.26801552 | D17: 0.41095163 | E17: 4.3710274 | F17: 4.3977462 | G17: =AVERAGE(E17:F17) -> 4.3843868 | H17: =2.35*G17 -> 10.303309 | I17: 0 | J17: 0.88225202
... A41: 245 | B41: 1 | C41: 0.028192403 | D41: 0.24437626 | E41: 3.0305042 | F41: 3.2727463 | G41: =AVERAGE(E41:F41) -> 3.1516253 | H41: =2.35*G41 -> 7.4063194 | I41: 0 | J41: 1

Sheet G4_GA0
A1: Gantry 4 commissioning data
A2: C:\Users\KAWCHUNG\NHS\(Canc) Radiotherapy - PBT Physics Team - PBT Physics Team\QAandCommissioning\Gantry 4\Commissioning\Spot Profiles\_GaussianFittingResults\Fits_G0_RS0_Dist0.xlsx
B4: Single Gaussian Fit
A5: Energy | B5: amplitude | C5: x_mean | D5: y_mean | E5: x_stddev | F5: y_stddev | G5: ave_stddev | H5: ave_fwhm | I5: theta | J5: amplitude
A6: 70 | B6: 0.9961756 | C6: 0.35918818 | D6: 0.17997282 | E6: 5.7765197 | F6: 5.9532775 | G6: =AVERAGE(E6:F6) -> 5.8648986 | H6: =2.35*G6 -> 13.782512 | I6: 0 | J6: 0.94874379
A7: 75 | B7: 1 | C7: -0.11045409 | D7: 0.42801718 | E7: 5.5260004 | F7: 5.6588164 | G7: =AVERAGE(E7:F7) -> 5.5924084 | H7: =2.35*G7 -> 13.14216 | I7: 0 | J7: 0.93507379
A8: 80 | B8: 1 | C8: 0.13728485 | D8: 0.53975971 | E8: 5.3518267 | F8: 5.5099014 | G8: =AVERAGE(E8:F8) -> 5.4308641 | H8: =2.35*G8 -> 12.762531 | I8: 0 | J8: 0.98189921
A9: 85 | B9: 1 | C9: -0.035075887 | D9: -0.28176885 | E9: 5.1666429 | F9: 5.3441553 | G9: =AVERAGE(E9:F9) -> 5.2553991 | H9: =2.35*G9 -> 12.350188 | I9: 0 | J9: 0.98348946
A10: 90 | B10: 1 | C10: 0.15785603 | D10: 0.21548521 | E10: 5.0015823 | F10: 5.2170099 | G10: =AVERAGE(E10:F10) -> 5.1092961 | H10: =2.35*G10 -> 12.006846 | I10: 0 | J10: 0.98957494
A11: 95 | B11: 1 | C11: -0.1587555 | D11: 0.26352429 | E11: 4.834026 | F11: 5.0842938 | G11: =AVERAGE(E11:F11) -> 4.9591599 | H11: =2.35*G11 -> 11.654026 | I11: 0 | J11: 0.99167765
A12: 100 | B12: 1 | C12: 0.020258406 | D12: 0.0014375934 | E12: 4.6781661 | F12: 4.9466649 | G12: =AVERAGE(E12:F12) -> 4.8124155 | H12: =2.35*G12 -> 11.309176 | I12: 0 | J12: 0.99281028
A13: 105 | B13: 1 | C13: 0.22528266 | D13: 0.30812787 | E13: 4.5526322 | F13: 4.8193167 | G13: =AVERAGE(E13:F13) -> 4.6859745 | H13: =2.35*G13 -> 11.01204 | I13: 0 | J13: 0.99535048
A14: 110 | B14: 1 | C14: -0.012086209 | D14: 0.32332932 | E14: 4.4218622 | F14: 4.6840865 | G14: =AVERAGE(E14:F14) -> 4.5529744 | H14: =2.35*G14 -> 10.69949 | I14: 0 | J14: 0.99575383
A15: 115 | B15: 1 | C15: 0.1793177 | D15: -0.00077477877 | E15: 4.334957 | F15: 4.5681316 | G15: =AVERAGE(E15:F15) -> 4.4515443 | H15: =2.35*G15 -> 10.461129 | I15: 0 | J15: 0.99737883
A16: 120 | B16: 1 | C16: 0.0083768219 | D16: 0.24009139 | E16: 4.2575805 | F16: 4.4940201 | G16: =AVERAGE(E16:F16) -> 4.3758003 | H16: =2.35*G16 -> 10.283131 | I16: 0 | J16: 0.99887994
A17: 125 | B17: 1 | C17: 0.070215391 | D17: 0.25165346 | E17: 4.1106435 | F17: 4.3519459 | G17: =AVERAGE(E17:F17) -> 4.2312947 | H17: =2.35*G17 -> 9.9435425 | I17: 0 | J17: 1
... A41: 245 | B41: 1 | C41: 0.080354634 | D41: 0.13570298 | E41: 3.0320053 | F41: 2.96908 | G41: =AVERAGE(E41:F41) -> 3.0005426 | H41: =2.35*G41 -> 7.0512752 | I41: 0 | J41: 0.99880309

Sheet G4_GA90
A1: Gantry 4 commissioning data
A2: C:\Users\KAWCHUNG\NHS\(Canc) Radiotherapy - PBT Physics Team - PBT Physics Team\QAandCommissioning\Gantry 4\Commissioning\Spot Profiles\_GaussianFittingResults\Fits_G90_RS0_Dist0.xlsx
B4: Single Gaussian Fit
A5: Energy | B5: amplitude | C5: x_mean | D5: y_mean | E5: x_stddev | F5: y_stddev | G5: ave_stddev | H5: ave_fwhm | I5: theta | J5: amplitude
A6: 70 | B6: 1 | C6: 0.088314835 | D6: 0.67568922 | E6: 5.8448561 | F6: 5.9233754 | G6: =AVERAGE(E6:F6) -> 5.8841157 | H6: =2.35*G6 -> 13.827672 | I6: 0 | J6: 0.7
A7: 75 | B7: 1 | C7: -0.05958262 | D7: 0.66483346 | E7: 5.6036502 | F7: 5.7370776 | G7: =AVERAGE(E7:F7) -> 5.6703639 | H7: =2.35*G7 -> 13.325355 | I7: 0 | J7: 0.90262253
A8: 80 | B8: 1 | C8: 0.42634651 | D8: 0.38897679 | E8: 5.4361371 | F8: 5.5378008 | G8: =AVERAGE(E8:F8) -> 5.486969 | H8: =2.35*G8 -> 12.894377 | I8: 0 | J8: 0.96028889
A9: 85 | B9: 1 | C9: 0.16757292 | D9: 0.37931208 | E9: 5.306813 | F9: 5.3696249 | G9: =AVERAGE(E9:F9) -> 5.3382189 | H9: =2.35*G9 -> 12.544814 | I9: 0 | J9: 0.98894168
A10: 90 | B10: 1 | C10: 0.067476472 | D10: 0.12540196 | E10: 5.0799373 | F10: 5.0961527 | G10: =AVERAGE(E10:F10) -> 5.088045 | H10: =2.35*G10 -> 11.956906 | I10: 0 | J10: 0.88102316
A11: 95 | B11: 1 | C11: 0.26614165 | D11: 0.10613524 | E11: 5.0066972 | F11: 4.9912321 | G11: =AVERAGE(E11:F11) -> 4.9989647 | H11: =2.35*G11 -> 11.747567 | I11: 0 | J11: 0.7
A12: 100 | B12: 1 | C12: 0.26329534 | D12: 0.36104184 | E12: 4.8664678 | F12: 4.832271 | G12: =AVERAGE(E12:F12) -> 4.8493694 | H12: =2.35*G12 -> 11.396018 | I12: 0 | J12: 0.99119987
A13: 105 | B13: 1 | C13: 0.4590261 | D13: 0.39023015 | E13: 4.72372 | F13: 4.6765415 | G13: =AVERAGE(E13:F13) -> 4.7001308 | H13: =2.35*G13 -> 11.045307 | I13: 0 | J13: 0.90548809
A14: 110 | B14: 1 | C14: 0.12489436 | D14: 0.4019339 | E14: 4.5847164 | F14: 4.5407142 | G14: =AVERAGE(E14:F14) -> 4.5627153 | H14: =2.35*G14 -> 10.722381 | I14: 0 | J14: 0.8911942
A15: 115 | B15: 1 | C15: 0.29126792 | D15: 0.33159179 | E15: 4.4991934 | F15: 4.4626079 | G15: =AVERAGE(E15:F15) -> 4.4809006 | H15: =2.35*G15 -> 10.530116 | I15: 0 | J15: 0.92968278
A16: 120 | B16: 1 | C16: 0.17486336 | D16: 0.35703541 | E16: 4.3573394 | F16: 4.3245776 | G16: =AVERAGE(E16:F16) -> 4.3409585 | H16: =2.35*G16 -> 10.201252 | I16: 0 | J16: 1
A17: 125 | B17: 1 | C17: 0.093941221 | D17: 0.31461906 | E17: 4.3309421 | F17: 4.3063745 | G17: =AVERAGE(E17:F17) -> 4.3186583 | H17: =2.35*G17 -> 10.148847 | I17: 0 | J17: 0.9988087
... A41: 245 | B41: 1 | C41: 0.058688319 | D41: 0.18755916 | E41: 2.9905367 | F41: 3.1047776 | G41: =AVERAGE(E41:F41) -> 3.0476571 | H41: =2.35*G41 -> 7.1619942 | I41: 0 | J41: 0.99866218

Sheet G4_GA180
A1: Gantry 4 commissioning data
A2: C:\Users\KAWCHUNG\NHS\(Canc) Radiotherapy - PBT Physics Team - PBT Physics Team\QAandCommissioning\Gantry 4\Commissioning\Spot Profiles\_GaussianFittingResults\Fits_G180_RS0_Dist0.xlsx
B4: Single Gaussian Fit
A5: Energy | B5: amplitude | C5: x_mean | D5: y_mean | E5: x_stddev | F5: y_stddev | G5: ave_stddev | H5: ave_fwhm | I5: theta | J5: amplitude
A6: 70 | B6: 1 | C6: -0.098184652 | D6: 0.28119115 | E6: 5.8015462 | F6: 5.9752593 | G6: =AVERAGE(E6:F6) -> 5.8884027 | H6: =2.35*G6 -> 13.837746 | I6: 0 | J6: 0.9755589
A7: 75 | B7: 1 | C7: -0.012561679 | D7: 0.086812353 | E7: 5.5838757 | F7: 5.6968134 | G7: =AVERAGE(E7:F7) -> 5.6403446 | H7: =2.35*G7 -> 13.25481 | I7: 0 | J7: 0.98056536
A8: 80 | B8: 1 | C8: 0.35237437 | D8: 0.2945164 | E8: 5.4448067 | F8: 5.5891018 | G8: =AVERAGE(E8:F8) -> 5.5169543 | H8: =2.35*G8 -> 12.964843 | I8: 0 | J8: 0.99375408
A9: 85 | B9: 1 | C9: 0.44799093 | D9: 0.60773641 | E9: 5.2356828 | F9: 5.4186102 | G9: =AVERAGE(E9:F9) -> 5.3271465 | H9: =2.35*G9 -> 12.518794 | I9: 0 | J9: 0.90610053
A10: 90 | B10: 1 | C10: 0.13011186 | D10: 0.087309188 | E10: 5.0141208 | F10: 5.2369457 | G10: =AVERAGE(E10:F10) -> 5.1255333 | H10: =2.35*G10 -> 12.045003 | I10: 0 | J10: 0.99289568
A11: 95 | B11: 1 | C11: 0.048854231 | D11: -0.0041031699 | E11: 4.8485093 | F11: 5.095311 | G11: =AVERAGE(E11:F11) -> 4.9719102 | H11: =2.35*G11 -> 11.683989 | I11: 0 | J11: 0.99410746
A12: 100 | B12: 1 | C12: -0.094230206 | D12: 0.50845466 | E12: 4.6878469 | F12: 4.9615008 | G12: =AVERAGE(E12:F12) -> 4.8246738 | H12: =2.35*G12 -> 11.337984 | I12: 0 | J12: 0.99415771
A13: 105 | B13: 1 | C13: 0.32667815 | D13: 0.48100688 | E13: 4.4870551 | F13: 4.7652634 | G13: =AVERAGE(E13:F13) -> 4.6261593 | H13: =2.35*G13 -> 10.871474 | I13: 0 | J13: 0.87950481
A14: 110 | B14: 1 | C14: -0.038386685 | D14: 0.47949821 | E14: 4.4120664 | F14: 4.689783 | G14: =AVERAGE(E14:F14) -> 4.5509247 | H14: =2.35*G14 -> 10.694673 | I14: 0 | J14: 0.99549486
A15: 115 | B15: 1 | C15: 0.17965739 | D15: 0.2075181 | E15: 4.3184382 | F15: 4.5895754 | G15: =AVERAGE(E15:F15) -> 4.4540068 | H15: =2.35*G15 -> 10.466916 | I15: 0 | J15: 0.94743169
A16: 120 | B16: 1 | C16: -0.0560738 | D16: 0.31472217 | E16: 4.2023943 | F16: 4.4634744 | G16: =AVERAGE(E16:F16) -> 4.3329344 | H16: =2.35*G16 -> 10.182396 | I16: 0 | J16: 0.91828288
A17: 125 | B17: 1 | C17: 0.19586718 | D17: 0.22137526 | E17: 4.1640353 | F17: 4.4167269 | G17: =AVERAGE(E17:F17) -> 4.2903811 | H17: =2.35*G17 -> 10.082396 | I17: 0 | J17: 0.90874242
... A41: 245 | B41: 1 | C41: 0.054328643 | D41: 0.22490219 | E41: 3.082229 | F41: 2.9752428 | G41: =AVERAGE(E41:F41) -> 3.0287359 | H41: =2.35*G41 -> 7.1175294 | I41: 0 | J41: 0.99968513

Sheet G4_GA270
A1: Gantry 4 commissioning data
A2: C:\Users\KAWCHUNG\NHS\(Canc) Radiotherapy - PBT Physics Team - PBT Physics Team\QAandCommissioning\Gantry 4\Commissioning\Spot Profiles\_GaussianFittingResults\Fits_G270_RS0_Dist0.xlsx
B4: Single Gaussian Fit
A5: Energy | B5: amplitude | C5: x_mean | D5: y_mean | E5: x_stddev | F5: y_stddev | G5: ave_stddev | H5: ave_fwhm | I5: theta | J5: amplitude
A6: 70 | B6: 1 | C6: 0.3079113 | D6: 0.13765636 | E6: 5.8059479 | F6: 5.7897785 | G6: =AVERAGE(E6:F6) -> 5.7978632 | H6: =2.35*G6 -> 13.624979 | I6: 0 | J6: 0.96578085
A7: 75 | B7: 1 | C7: 0.062792802 | D7: 0.63007909 | E7: 5.5764324 | F7: 5.5813475 | G7: =AVERAGE(E7:F7) -> 5.5788899 | H7: =2.35*G7 -> 13.110391 | I7: 0 | J7: 0.98645409
A8: 80 | B8: 1 | C8: 0.24468907 | D8: 0.2212624 | E8: 5.3753274 | F8: 5.3477142 | G8: =AVERAGE(E8:F8) -> 5.3615208 | H8: =2.35*G8 -> 12.599574 | I8: 0 | J8: 0.97833901
A9: 85 | B9: 1 | C9: 0.16520003 | D9: 0.34795915 | E9: 5.2430256 | F9: 5.1867646 | G9: =AVERAGE(E9:F9) -> 5.2148951 | H9: =2.35*G9 -> 12.255004 | I9: 0 | J9: 0.88677211
A10: 90 | B10: 1 | C10: 0.16071014 | D10: 0.19255084 | E10: 5.072171 | F10: 4.9856885 | G10: =AVERAGE(E10:F10) -> 5.0289297 | H10: =2.35*G10 -> 11.817985 | I10: 0 | J10: 0.85022183
A11: 95 | B11: 1 | C11: 0.36143361 | D11: 0.17276481 | E11: 4.9999426 | F11: 4.8781787 | G11: =AVERAGE(E11:F11) -> 4.9390606 | H11: =2.35*G11 -> 11.606793 | I11: 0 | J11: 0.84656511
A12: 100 | B12: 1 | C12: 0.18925257 | D12: 0.10000423 | E12: 4.8820657 | F12: 4.7566702 | G12: =AVERAGE(E12:F12) -> 4.8193679 | H12: =2.35*G12 -> 11.325515 | I12: 0 | J12: 0.9004464
A13: 105 | B13: 0.99703739 | C13: -0.12864224 | D13: -0.066750691 | E13: 4.64674 | F13: 4.5431477 | G13: =AVERAGE(E13:F13) -> 4.5949438 | H13: =2.35*G13 -> 10.798118 | I13: 0 | J13: 0.92300907
A14: 110 | B14: 1 | C14: -0.2316194 | D14: -0.11797745 | E14: 4.5907892 | F14: 4.4671322 | G14: =AVERAGE(E14:F14) -> 4.5289607 | H14: =2.35*G14 -> 10.643058 | I14: 0 | J14: 0.90999438
A15: 115 | B15: 1 | C15: 0.071695136 | D15: -0.13425405 | E15: 4.5094252 | F15: 4.3844536 | G15: =AVERAGE(E15:F15) -> 4.4469394 | H15: =2.35*G15 -> 10.450308 | I15: 0 | J15: 0.99859949
A16: 120 | B16: 1 | C16: 0.15118863 | D16: -0.037953912 | E16: 4.404309 | F16: 4.2805231 | G16: =AVERAGE(E16:F16) -> 4.342416 | H16: =2.35*G16 -> 10.204678 | I16: 0 | J16: 0.8878796
A17: 125 | B17: 1 | C17: -0.11069924 | D17: 0.13610892 | E17: 4.3783834 | F17: 4.2514956 | G17: =AVERAGE(E17:F17) -> 4.3149395 | H17: =2.35*G17 -> 10.140108 | I17: 0 | J17: 0.93320063
... A41: 245 | B41: 1 | C41: 0.03329615 | D41: 0.21181671 | E41: 2.9660098 | F41: 3.0828276 | G41: =AVERAGE(E41:F41) -> 3.0244187 | H41: =2.35*G41 -> 7.107384 | I41: 0 | J41: 0.99947007
